#VRML_SIM R2025a utf8

EXTERNPROTO "https://raw.githubusercontent.com/cyberbotics/webots/R2025a/projects/objects/backgrounds/protos/TexturedBackground.proto"
EXTERNPROTO "https://raw.githubusercontent.com/cyberbotics/webots/R2025a/projects/objects/backgrounds/protos/TexturedBackgroundLight.proto"
EXTERNPROTO "https://raw.githubusercontent.com/cyberbotics/webots/R2025a/projects/objects/floors/protos/RectangleArena.proto"

WorldInfo {
}
Viewpoint {
  orientation -0.3004511734628611 0.03850344589055602 0.9530197149164035 2.8985428705938454
  position 1.7695459979341621 -0.45698964360737215 2.7623247178931063
}
TexturedBackground {
}
TexturedBackgroundLight {
}
RectangleArena {
  translation 1.59215e-07 0 0.03
  rotation 0 1 0 5.30716e-06
  floorSize 4 4
}
DEF Obs1 Solid {
  translation 1.69614 -0.072898 0.142502
  rotation -0.0025754902978973823 0.002671230308971273 0.9999931156654838 -1.5881053071795863
  children [
    Shape {
      appearance PBRAppearance {
      }
      geometry Box {
        size 1 0.05 0.5
      }
    }
  ]
}
Robot {
  translation -1.7338560115393826 1.6538663204961663 0.06950808609803454
  rotation -0.005554559426433425 0.002935653500431737 0.9999802642093012 0.8776429494528892
  children [
    InertialUnit {
      name "imu"
    }
    DEF gps GPS {
      translation -0.05 -0.02 0.03
      children [
        Shape {
          appearance PBRAppearance {
          }
          geometry Cylinder {
            height 0.02
            radius 0.02
          }
        }
      ]
      boundingObject Shape {
        appearance PBRAppearance {
        }
        geometry Cylinder {
          height 0.02
          radius 0.02
        }
      }
      physics Physics {
      }
    }
    DEF lidar Lidar {
      translation 0.07 -0.02 0.04
      children [
        Shape {
          appearance PBRAppearance {
          }
          geometry Cylinder {
            height 0.025
            radius 0.025
          }
        }
      ]
      boundingObject Shape {
        appearance PBRAppearance {
        }
        geometry Cylinder {
          height 0.025
          radius 0.025
        }
      }
      physics Physics {
      }
      horizontalResolution 128
      fieldOfView 3.14
      verticalFieldOfView 0.1
      numberOfLayers 1
    }
    DEF BODY Shape {
      appearance PBRAppearance {
        baseColor 0.917647 0.145098 0.145098
        roughness 1
        metalness 0
      }
      geometry Box {
        size 0.2 0.1 0.05
      }
    }
    DEF WHEEL1 HingeJoint {
      jointParameters HingeJointParameters {
        position 7793.10276467962
        axis 0 1 0
        anchor 0.05 0.06 0
      }
      device [
        RotationalMotor {
          name "wheel1"
        }
      ]
      endPoint Solid {
        translation 0.04993605590521274 0.06043224674532349 0.0009056852525968212
        rotation 0.4326488860339056 0.6295268217638529 -0.6453765738648429 2.331201390614484
        children [
          DEF WHEEL Shape {
            appearance PBRAppearance {
              baseColor 0.305882 0.898039 0.25098
              roughness 1
              metalness 0
            }
            geometry Cylinder {
              height 0.02
              radius 0.04
              subdivision 24
            }
          }
        ]
        boundingObject USE WHEEL
        physics Physics {
        }
        linearVelocity 1.0820890998447528e-10 -7.719428009496631e-12 -1.6439863868817536e-13
        angularVelocity 1.1465769611029464e-09 -9.529523014648808e-10 -6.046294574843976e-11
      }
    }
    DEF WHEEL2 HingeJoint {
      jointParameters HingeJointParameters {
        position 5555.028664585378
        axis 0 1 0
        anchor 0.05 -0.06 0
      }
      device [
        RotationalMotor {
          name "wheel2"
        }
      ]
      endPoint Solid {
        translation 0.05000009661040845 -0.06000008469764562 2.2185452201691653e-06
        rotation -0.8906523752265544 -0.32151017948732274 0.3215113543707699 4.596842155132682
        children [
          USE WHEEL
        ]
        name "solid(1)"
        boundingObject USE WHEEL
        physics Physics {
        }
        linearVelocity 1.040520703035755e-10 -1.2728388654116508e-11 -2.2762840773145337e-14
        angularVelocity 3.2222673770734967e-13 -8.174673471788166e-13 -6.525002163626642e-11
      }
    }
    DEF WHEEL3 HingeJoint {
      jointParameters HingeJointParameters {
        position 7793.102572236732
        axis 0 1 0
        anchor -0.05 0.06 0
      }
      device [
        RotationalMotor {
          name "wheel3"
        }
      ]
      endPoint Solid {
        translation -0.04999681498629847 0.060000084994313085 3.3786147618948304e-06
        rotation -0.43124067555122597 -0.6379766821348813 0.6379790222274484 3.9558792371821525
        children [
          USE WHEEL
        ]
        name "solid(2)"
        boundingObject USE WHEEL
        physics Physics {
        }
        linearVelocity 1.0403778383982662e-10 -2.5308954803061506e-12 -2.5274335417919043e-14
        angularVelocity 1.1535282486486669e-10 -9.633619213296847e-11 -6.476901922510654e-11
      }
    }
    DEF WHEEL4 HingeJoint {
      jointParameters HingeJointParameters {
        position 5555.028039976564
        axis 0 1 0
        anchor -0.05 -0.06 0
      }
      device [
        RotationalMotor {
          name "wheel4"
        }
      ]
      endPoint Solid {
        translation -0.050000187233501664 -0.05999991499841628 2.0942226213639057e-06
        rotation -0.8908323816345723 -0.3212607276570467 0.3212619067000329 4.597042891446939
        children [
          USE WHEEL
        ]
        name "solid(3)"
        boundingObject USE WHEEL
        physics Physics {
        }
        linearVelocity 9.903156251953966e-11 -8.558706411192513e-12 2.336073880318903e-14
        angularVelocity -4.27582507774617e-12 3.011817431198e-12 -6.526961736960061e-11
      }
    }
    DEF DS_RIGHT DistanceSensor {
      translation 0.1 -0.03 0
      rotation 0 0 1 -0.3
      children [
        Shape {
          appearance PBRAppearance {
            baseColor 0.184314 0.596078 0.847059
            roughness 1
            metalness 0
          }
          geometry Box {
            size 0.01 0.01 0.01
          }
        }
      ]
      name "ds_right"
    }
    DEF DS_LEFT DistanceSensor {
      translation 0.1 0.03 0
      rotation 0 0 1 0.3
      children [
        Shape {
          appearance PBRAppearance {
            baseColor 0.184314 0.596078 0.847059
            roughness 1
            metalness 0
          }
          geometry Box {
            size 0.01 0.01 0.01
          }
        }
      ]
      name "ds_left"
    }
  ]
  boundingObject USE BODY
  physics Physics {
    density -1
    mass 1
  }
  controller "controlador"
  window "<none>"
  linearVelocity 1.0408651563776176e-10 -7.781973897251458e-12 -2.5823001935345276e-14
  angularVelocity -6.31771094171446e-13 1.5652180810066017e-15 -6.525330777248202e-11
}
Solid {
  translation 0 -0.96 0
  children [
    Shape {
      appearance PBRAppearance {
      }
      geometry Box {
        size 0.9 0.05 0.6
      }
    }
  ]
  name "solid(1)"
}
Solid {
  translation 0 1.15 0.09
  children [
    Shape {
      appearance PBRAppearance {
      }
      geometry Box {
        size 2 0.05 0.6
      }
    }
  ]
  name "solid(2)"
}
