#VRML_SIM R2025a utf8

EXTERNPROTO "https://raw.githubusercontent.com/cyberbotics/webots/R2025a/projects/objects/backgrounds/protos/TexturedBackground.proto"
EXTERNPROTO "https://raw.githubusercontent.com/cyberbotics/webots/R2025a/projects/objects/backgrounds/protos/TexturedBackgroundLight.proto"
EXTERNPROTO "https://raw.githubusercontent.com/cyberbotics/webots/R2025a/projects/objects/floors/protos/RectangleArena.proto"

WorldInfo {
}
Viewpoint {
  orientation 0.035374181403722615 0.9986242708885824 -0.0387070133472432 1.4821702841824524
  position -1.735434721830202 -0.8609632294444601 2.6982864216791564
}
TexturedBackground {
}
TexturedBackgroundLight {
}
RectangleArena {
  translation 1.59215e-07 0 0.03
  rotation 0 1 0 5.30716e-06
  floorSize 4 4
}
Robot {
  translation -1.41471 -1.65421 0.0658528
  rotation 0.010286103703590255 -0.002283961959076226 0.9999444882534072 1.4997403061004253
  children [
    Display {
      name "map_display"
    }
    InertialUnit {
      name "inertial_unit"
    }
    DEF gps GPS {
      translation -0.05 -0.02 0.03
      children [
        Shape {
          appearance PBRAppearance {
          }
          geometry Cylinder {
            height 0.02
            radius 0.02
          }
        }
      ]
      boundingObject Shape {
        appearance PBRAppearance {
        }
        geometry Cylinder {
          height 0.02
          radius 0.02
        }
      }
      physics Physics {
      }
    }
    DEF lidar Lidar {
      translation 0.07 -0.02 0.04
      children [
        Shape {
          appearance PBRAppearance {
          }
          geometry Cylinder {
            height 0.025
            radius 0.025
          }
        }
      ]
      boundingObject Shape {
        appearance PBRAppearance {
        }
        geometry Cylinder {
          height 0.025
          radius 0.025
        }
      }
      physics Physics {
      }
      horizontalResolution 128
      fieldOfView 3.14
      verticalFieldOfView 0.1
      numberOfLayers 1
    }
    DEF BODY Shape {
      appearance PBRAppearance {
        baseColor 0.917647 0.145098 0.145098
        roughness 1
        metalness 0
      }
      geometry Box {
        size 0.2 0.1 0.05
      }
    }
    DEF WHEEL1 HingeJoint {
      jointParameters HingeJointParameters {
        position 9337.190494962535
        axis 0 1 0
        anchor 0.05 0.06 0
      }
      device [
        RotationalMotor {
          name "wheel1"
        }
      ]
      endPoint Solid {
        translation 0.04909464982601026 0.06043224674532349 -6.852507925038072e-05
        rotation 0.966022335659465 0.1772668264496869 -0.1880885941451224 1.6236777461774463
        children [
          DEF WHEEL Shape {
            appearance PBRAppearance {
              baseColor 0.305882 0.898039 0.25098
              roughness 1
              metalness 0
            }
            geometry Cylinder {
              height 0.02
              radius 0.04
              subdivision 24
            }
          }
        ]
        boundingObject USE WHEEL
        physics Physics {
        }
      }
    }
    DEF WHEEL2 HingeJoint {
      jointParameters HingeJointParameters {
        position 7507.022581843068
        axis 0 1 0
        anchor 0.05 -0.06 0
      }
      device [
        RotationalMotor {
          name "wheel2"
        }
      ]
      endPoint Solid {
        translation 0.049998012552530745 -0.06000008469764562 -9.906205236834591e-07
        rotation 0.6491447131278273 -0.537870327589773 0.5378723381218454 1.9900485698012567
        children [
          USE WHEEL
        ]
        name "solid(1)"
        boundingObject USE WHEEL
        physics Physics {
        }
      }
    }
    DEF WHEEL3 HingeJoint {
      jointParameters HingeJointParameters {
        position 9337.190358625345
        axis 0 1 0
        anchor -0.05 0.06 0
      }
      device [
        RotationalMotor {
          name "wheel3"
        }
      ]
      endPoint Solid {
        translation -0.05000339450656291 0.060000084994313085 3.168071208578251e-06
        rotation -0.9654835043133454 -0.18417568670602888 0.18417632672302106 4.6772662368987445
        children [
          USE WHEEL
        ]
        name "solid(2)"
        boundingObject USE WHEEL
        physics Physics {
        }
      }
    }
    DEF WHEEL4 HingeJoint {
      jointParameters HingeJointParameters {
        position 7507.02208477057
        axis 0 1 0
        anchor -0.05 -0.06 0
      }
      device [
        RotationalMotor {
          name "wheel4"
        }
      ]
      endPoint Solid {
        translation -0.050001741295490766 -0.05999991499841628 -1.178437434006157e-06
        rotation 0.6489546990613213 -0.5379849598784943 0.5379869715065273 1.9903159644976307
        children [
          USE WHEEL
        ]
        name "solid(3)"
        boundingObject USE WHEEL
        physics Physics {
        }
      }
    }
    DEF DS_RIGHT DistanceSensor {
      translation 0.1 -0.03 0
      rotation 0 0 1 -0.3
      children [
        Shape {
          appearance PBRAppearance {
            baseColor 0.184314 0.596078 0.847059
            roughness 1
            metalness 0
          }
          geometry Box {
            size 0.01 0.01 0.01
          }
        }
      ]
      name "ds_right"
    }
    DEF DS_LEFT DistanceSensor {
      translation 0.1 0.03 0
      rotation 0 0 1 0.3
      children [
        Shape {
          appearance PBRAppearance {
            baseColor 0.184314 0.596078 0.847059
            roughness 1
            metalness 0
          }
          geometry Box {
            size 0.01 0.01 0.01
          }
        }
      ]
      name "ds_left"
    }
  ]
  boundingObject USE BODY
  physics Physics {
    density -1
    mass 1
  }
  controller "controlador"
  window "<none>"
}
Solid {
  translation -0.759613 -0.73351 0.32
  rotation 0 0 1 -1.570795613280012
  children [
    Shape {
      appearance PBRAppearance {
      }
      geometry Box {
        size 2.5 0.05 0.6
      }
    }
  ]
  name "solid(1)"
  boundingObject Shape {
    appearance PBRAppearance {
    }
    geometry Box {
      size 2.5 0.05 0.6
    }
  }
}
Solid {
  translation 0.750387 0.79649 0.32
  rotation 0 0 1 -1.570795613280012
  children [
    Shape {
      appearance PBRAppearance {
      }
      geometry Box {
        size 2.5 0.05 0.6
      }
    }
  ]
  name "solid(2)"
  boundingObject Shape {
    appearance PBRAppearance {
    }
    geometry Box {
      size 2.5 0.05 0.6
    }
  }
}
Solid {
  translation -1.48961 1.23649 1.17
  rotation 0 0 1 -1.570795613280012
  children [
    Shape {
      appearance PBRAppearance {
      }
      geometry Box {
        size 0.1 0.1 0.6
      }
    }
  ]
  name "solid(3)"
  boundingObject Shape {
    appearance PBRAppearance {
    }
    geometry Box {
      size 0.1 0.1 0.6
    }
  }
}
Billboard {
  children [
    Shape {
      appearance PBRAppearance {
        baseColor 0 1 1
        emissiveColor 0 1 1
      }
    }
  ]
}
